<robot name="wx250s">


  <link name="floor">
    <visual>
      <origin xyz="0 0 0" rpy="0 0 0"/>
      <geometry>
        <box size="1 1 0.01"/>
      </geometry>
    </visual>
    <collision>
      <origin xyz="0 0 0" rpy="0 0 0"/>
      <geometry>
        <box size="1 1 0.01"/>
      </geometry>
    </collision>
  </link>

  <joint name="marcel_joint_floor" type="fixed">
    <parent link="floor"/>
    <child link="link0"/>
    <origin xyz="-0.3 0 0" rpy="1.5708 0 -1.5708"/>
  </joint>

  <joint name="wx250s_joint_floor" type="fixed">
    <parent link="floor"/>
    <child link="wx250s/base_link"/>
    <origin xyz="0.3 0 0" rpy="0 0 3.1415"/>
  </joint>





  <link name="link0">
    <visual>
      <origin xyz="0 0 0" rpy="0 0 0"/>
      <geometry>
        <mesh filename="package://meshes/marcel_meshes/link0.dae" scale="0.001 0.001 0.001"/>
      </geometry>
    </visual>
    <collision>
      <origin xyz="0 0 0" rpy="0 0 0"/>
      <geometry>
        <mesh filename="package://meshes/marcel_meshes/link0.dae" scale="0.001 0.001 0.001"/>
      </geometry>
    </collision>
  </link>


  <link name="link1">
    <visual>
      <origin xyz="0 0 0.03525" rpy="0 0 0"/>
      <geometry>
        <mesh filename="package://meshes/marcel_meshes/link1.dae" scale="0.001 0.001 0.001"/>
      </geometry>
    </visual>
    <collision>
      <origin xyz="0 0 0.02525" rpy="0 0 0"/>
      <geometry>
        <mesh filename="package://meshes/marcel_meshes/link1.dae" scale="0.001 0.001 0.001"/>
      </geometry>
    </collision>
  </link>

  <joint name="joint0" type="revolute">
    <parent link="link0"/>
    <child link="link1"/>
    <origin xyz="0 0 -0.03525" rpy="0 0 0"/>
    <axis xyz="0 1 0"/>
    <limit lower="-1.57" upper="1.57" effort="100" velocity="1"/>
  </joint>

  <link name="link2">
    <visual>
      <origin xyz="0 -0.0533 0.03525" rpy="0 0 0"/>
      <geometry>
        <mesh filename="package://meshes/marcel_meshes/link2.dae" scale="0.001 0.001 0.001"/>
      </geometry>
    </visual>
    <collision>
      <origin xyz="0 -0.0533 0.03525" rpy="0 0 0"/>
      <geometry>
        <mesh filename="package://meshes/marcel_meshes/link2.dae" scale="0.001 0.001 0.001"/>
      </geometry>
    </collision>
  </link>

  <joint name="joint1" type="revolute">
    <parent link="link1"/>
    <child link="link2"/>
    <origin xyz="0 0.0533 0" rpy="0 0 0"/>
    <axis xyz="1 0 0"/>
    <limit lower="-0.174533" upper="1.39626" effort="100" velocity="1"/>
  </joint>

  <link name="link3">
    <visual>
      <origin xyz="0 -0.15976 0.0605" rpy="0 0 0"/>
      <geometry>
        <mesh filename="package://meshes/marcel_meshes/link3.dae" scale="0.001 0.001 0.001"/>
      </geometry>
    </visual>
    <collision>
      <origin xyz="0 -0.15976 0.0605" rpy="0 0 0"/>
      <geometry>
        <mesh filename="package://meshes/marcel_meshes/link3.dae" scale="0.001 0.001 0.001"/>
      </geometry>
    </collision>
  </link>

  <joint name="joint2" type="revolute">
    <parent link="link2"/>
    <child link="link3"/>
    <origin xyz="0 0.10646 -0.02525" rpy="0 0 0"/>
    <axis xyz="1 0 0"/>
    <limit lower="-1.74533" upper="1.39626" effort="100" velocity="1"/>
  </joint>

  <link name="link4">
    <visual>
      <origin xyz="0 -0.16092 0.1755" rpy="0 0 0"/>
      <geometry>
        <mesh filename="package://meshes/marcel_meshes/link4.dae" scale="0.001 0.001 0.001"/>
      </geometry>
    </visual>
    <collision>
      <origin xyz="0 -0.16092 0.1755" rpy="0 0 0"/>
      <geometry>
        <mesh filename="package://meshes/marcel_meshes/link4.dae" scale="0.001 0.001 0.001"/>
      </geometry>
    </collision>
  </link>

  <joint name="joint3" type="revolute">
    <parent link="link3"/>
    <child link="link4"/>
    <origin xyz="0 0.00116 -0.115" rpy="0 0 0"/>
    <axis xyz="1 0 0"/>
    <limit lower="-1.57" upper="1.57" effort="100" velocity="1"/>
  </joint>

  <!-- Link 5 -->
  <link name="link5">
    <visual>
      <origin xyz="-0.00136 -0.16093 0.22009" rpy="0 0 0"/>
      <geometry>
        <mesh filename="package://meshes/marcel_meshes/link5.dae" scale="0.001 0.001 0.001"/>
      </geometry>
    </visual>
    <collision>
      <origin xyz="-0.00136 -0.16093 0.22009" rpy="0 0 0"/>
      <geometry>
        <mesh filename="package://meshes/marcel_meshes/link5.dae" scale="0.001 0.001 0.001"/>
      </geometry>
    </collision>
  </link>

  <joint name="joint4" type="revolute">
    <parent link="link4"/>
    <child link="link5"/>
    <origin xyz="0.00136 0 -0.04459" rpy="0 0 0"/>
    <axis xyz="0 0 1"/>
    <limit lower="-3.14" upper="3.14" effort="100" velocity="1"/>
  </joint>

  <!-- Link 6 -->
  <link name="link6">
    <visual>
      <origin xyz="-0.00876 -0.16093 0.23324" rpy="0 0 0"/>
      <geometry>
        <mesh filename="package://meshes/marcel_meshes/link6.dae" scale="0.001 0.001 0.001"/>
      </geometry>
    </visual>
    <collision>
      <origin xyz="0 0 0" rpy="0 0 0"/>
      <geometry>
        <mesh filename="package://meshes/marcel_meshes/link6.dae" scale="0.001 0.001 0.001"/>
      </geometry>
    </collision>
  </link>

  <joint name="joint5" type="revolute">
    <parent link="link5"/>
    <child link="link6"/>
    <origin xyz="0.0074 0 -0.01315" rpy="0 0 0"/>
    <axis xyz="0 -1 0"/>
    <limit lower="-0.0872665" upper="1.39626" effort="100" velocity="1"/>
  </joint>

  <link name='ball'>
    <origin xyz="0 0 0" rpy="0 0 0"/>
  </link>
  <joint name="ball" type="fixed">
    <parent link="link5"/>
    <child link="ball"/>
    <origin xyz="-0.01462 -0.00054 -0.05572" rpy="0 0 0"/>
  </joint>








  <material name="interbotix_black">
    <texture filename="package://meshes/interbotix_black.png" />
  </material>
  <link name="wx250s/base_link">
    <visual>
      <origin rpy="0 0 1.5707963267948966" xyz="0 0 0" />
      <geometry>
        <mesh filename="package://meshes/wx250s_meshes/wx250s_1_base.dae" scale="0.001 0.001 0.001" />
      </geometry>
      <material name="interbotix_black" />
    </visual>
    <collision>
      <origin rpy="0 0 1.5707963267948966" xyz="0 0 0" />
      <geometry>
        <mesh filename="package://meshes/wx250s_meshes/wx250s_1_base.dae" scale="0.001 0.001 0.001" />
      </geometry>
    </collision>
    <inertial>
      <origin rpy="0 0 1.5707963267948966" xyz="-0.0380446000 0.0006138920 0.0193354000" />
      <mass value="0.538736" />
      <inertia ixx="0.0021150000" ixy="-0.0000163500" ixz="0.0000006998" iyy="0.0006921000" iyz="0.0000464200" izz="0.0025240000" />
    </inertial>
  </link>
  <joint name="waist" type="revolute">
    <axis xyz="0 0 1" />
    <limit effort="10" lower="-3.141582653589793" upper="3.141582653589793" velocity="3.141592653589793" />
    <origin rpy="0 0 0" xyz="0 0 0.072" />
    <parent link="wx250s/base_link" />
    <child link="wx250s/shoulder_link" />
    <dynamics friction="0.1" />
  </joint>
  <transmission name="trans_waist">
    <type>transmission_interface/SimpleTransmission</type>
    <joint name="waist">
      <hardwareInterface>hardware_interface/EffortJointInterface</hardwareInterface>
    </joint>
    <actuator name="waist_motor">
      <mechanicalReduction>1</mechanicalReduction>
    </actuator>
  </transmission>
  <link name="wx250s/shoulder_link">
    <visual>
      <origin rpy="0 0 1.5707963267948966" xyz="0 0 -0.003" />
      <geometry>
        <mesh filename="package://meshes/wx250s_meshes/wx250s_2_shoulder.dae" scale="0.001 0.001 0.001" />
      </geometry>
      <material name="interbotix_black" />
    </visual>
    <collision>
      <origin rpy="0 0 1.5707963267948966" xyz="0 0 -0.003" />
      <geometry>
        <mesh filename="package://meshes/wx250s_meshes/wx250s_2_shoulder.dae" scale="0.001 0.001 0.001" />
      </geometry>
    </collision>
    <inertial>
      <origin rpy="0 0 1.5707963267948966" xyz="0.0000223482 0.0000414609 0.0066287000" />
      <mass value="0.480879" />
      <inertia ixx="0.0003790000" ixy="0.0000000022" ixz="-0.0000003561" iyy="0.0005557000" iyz="0.0000012245" izz="0.0005889000" />
    </inertial>
  </link>
  <joint name="shoulder" type="revolute">
    <axis xyz="0 1 0" />
    <limit effort="20" lower="-1.8849555921538759" upper="1.9896753472735358" velocity="3.141592653589793" />
    <origin rpy="0 0 0" xyz="0 0 0.03865" />
    <parent link="wx250s/shoulder_link" />
    <child link="wx250s/upper_arm_link" />
    <dynamics friction="0.1" />
  </joint>
  <transmission name="trans_shoulder">
    <type>transmission_interface/SimpleTransmission</type>
    <joint name="shoulder">
      <hardwareInterface>hardware_interface/EffortJointInterface</hardwareInterface>
    </joint>
    <actuator name="shoulder_motor">
      <mechanicalReduction>1</mechanicalReduction>
    </actuator>
  </transmission>
  <link name="wx250s/upper_arm_link">
    <visual>
      <origin rpy="0 0 1.5707963267948966" xyz="0 0 0" />
      <geometry>
        <mesh filename="package://meshes/wx250s_meshes/wx250s_3_upper_arm.dae" scale="0.001 0.001 0.001" />
      </geometry>
      <material name="interbotix_black" />
    </visual>
    <collision>
      <origin rpy="0 0 1.5707963267948966" xyz="0 0 0" />
      <geometry>
        <mesh filename="package://meshes/wx250s_meshes/wx250s_3_upper_arm.dae" scale="0.001 0.001 0.001" />
      </geometry>
    </collision>
    <inertial>
      <origin rpy="0 0 1.5707963267948966" xyz="0.0171605000 0.0000002725 0.1913230000" />
      <mass value="0.430811" />
      <inertia ixx="0.0034630000" ixy="-0.0000000001" ixz="-0.0000000002" iyy="0.0035870000" iyz="0.0004272000" izz="0.0004566000" />
    </inertial>
  </link>
  <joint name="elbow" type="revolute">
    <axis xyz="0 1 0" />
    <limit effort="15" lower="-2.1467549799530254" upper="1.6057029118347832" velocity="3.141592653589793" />
    <origin rpy="0 0 0" xyz="0.04975 0 0.25" />
    <parent link="wx250s/upper_arm_link" />
    <child link="wx250s/upper_forearm_link" />
    <dynamics friction="0.1" />
  </joint>
  <transmission name="trans_elbow">
    <type>transmission_interface/SimpleTransmission</type>
    <joint name="elbow">
      <hardwareInterface>hardware_interface/EffortJointInterface</hardwareInterface>
    </joint>
    <actuator name="elbow_motor">
      <mechanicalReduction>1</mechanicalReduction>
    </actuator>
  </transmission>
  <link name="wx250s/upper_forearm_link">
    <visual>
      <origin rpy="0 0 0" xyz="0 0 0" />
      <geometry>
        <mesh filename="package://meshes/wx250s_meshes/wx250s_4_upper_forearm.dae" scale="0.001 0.001 0.001" />
      </geometry>
      <material name="interbotix_black" />
    </visual>
    <collision>
      <origin rpy="0 0 0" xyz="0 0 0" />
      <geometry>
        <mesh filename="package://meshes/wx250s_meshes/wx250s_4_upper_forearm.dae" scale="0.001 0.001 0.001" />
      </geometry>
    </collision>
    <inertial>
      <origin rpy="0 0 0" xyz="0.1079630000 0.0001158760 0" />
      <mass value="0.234589" />
      <inertia ixx="0.0000397100" ixy="0.0000023528" ixz="0" iyy="0.0008878000" iyz="0" izz="0.0008880000" />
    </inertial>
  </link>
  <joint name="forearm_roll" type="revolute">
    <axis xyz="1 0 0" />
    <limit effort="2" lower="-3.141582653589793" upper="3.141582653589793" velocity="3.141592653589793" />
    <origin rpy="0 0 0" xyz="0.175 0 0" />
    <parent link="wx250s/upper_forearm_link" />
    <child link="wx250s/lower_forearm_link" />
    <dynamics friction="0.1" />
  </joint>
  <transmission name="trans_forearm_roll">
    <type>transmission_interface/SimpleTransmission</type>
    <joint name="forearm_roll">
      <hardwareInterface>hardware_interface/EffortJointInterface</hardwareInterface>
    </joint>
    <actuator name="forearm_roll_motor">
      <mechanicalReduction>1</mechanicalReduction>
    </actuator>
  </transmission>
  <link name="wx250s/lower_forearm_link">
    <visual>
      <origin rpy="3.141592653589793 0 0" xyz="0 0 0" />
      <geometry>
        <mesh filename="package://meshes/wx250s_meshes/wx250s_5_lower_forearm.dae" scale="0.001 0.001 0.001" />
      </geometry>
      <material name="interbotix_black" />
    </visual>
    <collision>
      <origin rpy="3.141592653589793 0 0" xyz="0 0 0" />
      <geometry>
        <mesh filename="package://meshes/wx250s_meshes/wx250s_5_lower_forearm.dae" scale="0.001 0.001 0.001" />
      </geometry>
    </collision>
    <inertial>
      <origin rpy="3.141592653589793 0 0" xyz="0.0374395000 0.0052225200 0" />
      <mass value="0.220991" />
      <inertia ixx="0.0000636900" ixy="-0.0000229200" ixz="0" iyy="0.0001677000" iyz="0" izz="0.0001834000" />
    </inertial>
  </link>
  <joint name="wrist_angle" type="revolute">
    <axis xyz="0 1 0" />
    <limit effort="5" lower="-1.7453292519943295" upper="2.1467549799530254" velocity="3.141592653589793" />
    <origin rpy="0 0 0" xyz="0.075 0 0" />
    <parent link="wx250s/lower_forearm_link" />
    <child link="wx250s/wrist_link" />
    <dynamics friction="0.1" />
  </joint>
  <transmission name="trans_wrist_angle">
    <type>transmission_interface/SimpleTransmission</type>
    <joint name="wrist_angle">
      <hardwareInterface>hardware_interface/EffortJointInterface</hardwareInterface>
    </joint>
    <actuator name="wrist_angle_motor">
      <mechanicalReduction>1</mechanicalReduction>
    </actuator>
  </transmission>
  <link name="wx250s/wrist_link">
    <visual>
      <origin rpy="0 0 1.5707963267948966" xyz="0 0 0" />
      <geometry>
        <mesh filename="package://meshes/wx250s_meshes/wx250s_6_wrist.dae" scale="0.001 0.001 0.001" />
      </geometry>
      <material name="interbotix_black" />
    </visual>
    <collision>
      <origin rpy="0 0 1.5707963267948966" xyz="0 0 0" />
      <geometry>
        <mesh filename="package://meshes/wx250s_meshes/wx250s_6_wrist.dae" scale="0.001 0.001 0.001" />
      </geometry>
    </collision>
    <inertial>
      <origin rpy="0 0 1.5707963267948966" xyz="0.0423600000 -0.0000106630 0.0105770000" />
      <mass value="0.084957" />
      <inertia ixx="0.0000308200" ixy="0.0000000191" ixz="0.0000000023" iyy="0.0000282200" iyz="0.0000025481" izz="0.0000315200" />
    </inertial>
  </link>
  <joint name="wrist_rotate" type="revolute">
    <axis xyz="1 0 0" />
    <limit effort="1" lower="-3.141582653589793" upper="3.141582653589793" velocity="3.141592653589793" />
    <origin rpy="0 0 0" xyz="0.065 0 0" />
    <parent link="wx250s/wrist_link" />
    <child link="wx250s/gripper_link" />
    <dynamics friction="0.1" />
  </joint>
  <transmission name="trans_wrist_rotate">
    <type>transmission_interface/SimpleTransmission</type>
    <joint name="wrist_rotate">
      <hardwareInterface>hardware_interface/EffortJointInterface</hardwareInterface>
    </joint>
    <actuator name="wrist_rotate_motor">
      <mechanicalReduction>1</mechanicalReduction>
    </actuator>
  </transmission>
  <link name="wx250s/gripper_link">
    <visual>
      <origin rpy="0 0 1.5707963267948966" xyz="-0.02 0 0" />
      <geometry>
        <mesh filename="package://meshes/wx250s_meshes/wx250s_7_gripper.dae" scale="0.001 0.001 0.001" />
      </geometry>
      <material name="interbotix_black" />
    </visual>
    <collision>
      <origin rpy="0 0 1.5707963267948966" xyz="-0.02 0 0" />
      <geometry>
        <mesh filename="package://meshes/wx250s_meshes/wx250s_7_gripper.dae" scale="0.001 0.001 0.001" />
      </geometry>
    </collision>
    <inertial>
      <origin rpy="0 0 1.5707963267948966" xyz="0.0216310000 0.0000002516 0.0114100000" />
      <mass value="0.072885" />
      <inertia ixx="0.0000253700" ixy="0.0000000000" ixz="0.0000000000" iyy="0.0000183600" iyz="0.0000004340" izz="0.0000167400" />
    </inertial>
  </link>
  <joint name="ee_arm" type="fixed">
    <axis xyz="1 0 0" />
    <origin rpy="0 0 0" xyz="0.043 0 0" />
    <parent link="wx250s/gripper_link" />
    <child link="wx250s/ee_arm_link" />
  </joint>
  <link name="wx250s/ee_arm_link">
    <inertial>
      <mass value="0.001" />
      <inertia ixx="0.001" ixy="0" ixz="0" iyy="0.001" iyz="0" izz="0.001" />
    </inertial>
  </link>
  <joint name="gripper" type="continuous">
    <axis xyz="1 0 0" />
    <limit effort="1" velocity="3.141592653589793" />
    <origin rpy="0 0 0" xyz="0.0055 0 0" />
    <parent link="wx250s/ee_arm_link" />
    <child link="wx250s/gripper_prop_link" />
    <dynamics friction="0.1" />
  </joint>
  <transmission name="trans_gripper">
    <type>transmission_interface/SimpleTransmission</type>
    <joint name="gripper">
      <hardwareInterface>hardware_interface/EffortJointInterface</hardwareInterface>
    </joint>
    <actuator name="gripper_motor">
      <mechanicalReduction>1</mechanicalReduction>
    </actuator>
  </transmission>
  <link name="wx250s/gripper_prop_link">
    <visual>
      <origin rpy="0 0 1.5707963267948966" xyz="-0.0685 0 0" />
      <geometry>
        <mesh filename="package://meshes/wx250s_meshes/wx250s_8_gripper_prop.dae" scale="0.001 0.001 0.001" />
      </geometry>
      <material name="interbotix_black" />
    </visual>
    <collision>
      <origin rpy="0 0 1.5707963267948966" xyz="-0.0685 0 0" />
      <geometry>
        <mesh filename="package://meshes/wx250s_meshes/wx250s_8_gripper_prop.dae" scale="0.001 0.001 0.001" />
      </geometry>
    </collision>
    <inertial>
      <origin rpy="0 0 1.5707963267948966" xyz="0.0008460000 -0.0000016817 0.0000420000" />
      <mass value="0.00434" />
      <inertia ixx="0.0000005923" ixy="0.0000000000" ixz="0.0000003195" iyy="0.0000011156" iyz="-0.0000000004" izz="0.0000005743" />
    </inertial>
  </link>
  
  
  <joint name="gripper_bar" type="fixed">
    <axis xyz="1 0 0" />
    <origin rpy="0 0 0" xyz="0 0 0" />
    <parent link="wx250s/ee_arm_link" />
    <child link="wx250s/gripper_bar_link" />
  </joint>
  <link name="wx250s/gripper_bar_link">
    <visual>
      <origin rpy="0 0 1.5707963267948966" xyz="-0.063 0 0" />
      <geometry>
        <mesh filename="package://meshes/wx250s_meshes/wx250s_9_gripper_bar.dae" scale="0.001 0.001 0.001" />
      </geometry>
      <material name="interbotix_black" />
    </visual>
    <collision>
      <origin rpy="0 0 1.5707963267948966" xyz="-0.063 0 0" />
      <geometry>
        <mesh filename="package://meshes/wx250s_meshes/wx250s_9_gripper_bar.dae" scale="0.001 0.001 0.001" />
      </geometry>
    </collision>
    <inertial>
      <origin rpy="0 0 1.5707963267948966" xyz="0.0096870000 0.0000008177 0.0049620000" />
      <mass value="0.034199" />
      <inertia ixx="0.0000074125" ixy="-0.0000000008" ixz="-0.0000000006" iyy="0.0000284300" iyz="-0.0000013889" izz="0.0000286000" />
    </inertial>
  </link>
  <joint name="ee_bar" type="fixed">
    <axis xyz="1 0 0" />
    <origin rpy="0 0 0" xyz="0.023 0 0" />
    <parent link="wx250s/gripper_bar_link" />
    <child link="wx250s/fingers_link" />
  </joint>
  <link name="wx250s/fingers_link">
    <inertial>
      <mass value="0.001" />
      <inertia ixx="0.001" ixy="0" ixz="0" iyy="0.001" iyz="0" izz="0.001" />
    </inertial>
  </link>
  
  <joint name="left_finger" type="prismatic">
    <axis xyz="0 1 0" />
    <limit effort="5" lower="0.015" upper="0.037" velocity="1" />
    <origin rpy="0 0 0" xyz="0 0 0" />
    <parent link="wx250s/fingers_link" />
    <child link="wx250s/left_finger_link" />
    <dynamics friction="0.1" />
  </joint>
  <transmission name="trans_left_finger">
    <type>transmission_interface/SimpleTransmission</type>
    <joint name="left_finger">
      <hardwareInterface>hardware_interface/EffortJointInterface</hardwareInterface>
    </joint>
    <actuator name="left_finger_motor">
      <mechanicalReduction>1</mechanicalReduction>
    </actuator>
  </transmission>
  <link name="wx250s/left_finger_link">
    <visual>
      <origin rpy="3.141592653589793 3.141592653589793 0" xyz="0 0.005 0" />
      <geometry>
        <mesh filename="package://meshes/wx250s_meshes/wx250s_10_gripper_finger.dae" scale="0.001 0.001 0.001" />
      </geometry>
      <material name="interbotix_black" />
    </visual>
    <collision>
      <origin rpy="3.141592653589793 3.141592653589793 0" xyz="0 0.005 0" />
      <geometry>
        <mesh filename="package://meshes/wx250s_meshes/wx250s_10_gripper_finger.dae" scale="0.001 0.001 0.001" />
      </geometry>
    </collision>
    <inertial>
      <origin rpy="3.141592653589793 3.141592653589793 1.5707963267948966" xyz="0.0138160000 0.0000000000 0.0000000000" />
      <mass value="0.016246" />
      <inertia ixx="0.0000047310" ixy="-0.0000004560" ixz="0.0000000000" iyy="0.0000015506" iyz="0.0000000000" izz="0.0000037467" />
    </inertial>
  </link>
  <joint name="right_finger" type="prismatic">
    <axis xyz="0 1 0" />
    <limit effort="5" lower="-0.037" upper="-0.015" velocity="1" />
    <origin rpy="0 0 0" xyz="0 0 0" />
    <parent link="wx250s/fingers_link" />
    <child link="wx250s/right_finger_link" />
    <dynamics friction="0.1" />
    <mimic joint="left_finger" multiplier="-1" offset="0" />
  </joint>
  <transmission name="trans_right_finger">
    <type>transmission_interface/SimpleTransmission</type>
    <joint name="right_finger">
      <hardwareInterface>hardware_interface/EffortJointInterface</hardwareInterface>
    </joint>
    <actuator name="right_finger_motor">
      <mechanicalReduction>1</mechanicalReduction>
    </actuator>
  </transmission>
  <link name="wx250s/right_finger_link">
    <visual>
      <origin rpy="0 3.141592653589793 0" xyz="0 -0.005 0" />
      <geometry>
        <mesh filename="package://meshes/wx250s_meshes/wx250s_10_gripper_finger.dae" scale="0.001 0.001 0.001" />
      </geometry>
      <material name="interbotix_black" />
    </visual>
    <collision>
      <origin rpy="0 3.141592653589793 0" xyz="0 -0.005 0" />
      <geometry>
        <mesh filename="package://meshes/wx250s_meshes/wx250s_10_gripper_finger.dae" scale="0.001 0.001 0.001" />
      </geometry>
    </collision>
    <inertial>
      <origin rpy="0 3.141592653589793 1.5707963267948966" xyz="0.0138160000 0.0000000000  0.0000000000" />
      <mass value="0.016246" />
      <inertia ixx="0.0000047310" ixy="0.0000004560" ixz="0.0000000000" iyy="0.0000015506" iyz="0.0000000000" izz="0.0000037467" />
    </inertial>
  </link>
  <joint name="ee_gripper" type="fixed">
    <axis xyz="1 0 0" />
    <origin rpy="0 0 0" xyz="0.027575 0 0" />
    <parent link="wx250s/fingers_link" />
    <child link="wx250s/ee_gripper_link" />
  </joint>
  <link name="wx250s/ee_gripper_link">
    <inertial>
      <mass value="0.001" />
      <inertia ixx="0.001" ixy="0" ixz="0" iyy="0.001" iyz="0" izz="0.001" />
    </inertial>
  </link>






</robot>