<?xml version="1.0"?>
<robot  xmlns:xacro="http://www.ros.org/wiki/xacro" name="firefighter" >
	
<xacro:property name="width" value=".2" />
  <!-- World -->
  <link name="world">
    <origin xyz= "0 0 0" rpy = "0 0 0"/>
  </link>
  <joint name="world_to_left_g_base" type="fixed">
    <parent link="world"/>
    <child link="left_g_base"/>
    <origin xyz= "-0.25 0 0" rpy = "0 0 1.5708"/>
  </joint>
  <joint name="world_to_right_g_base" type="fixed">
    <parent link="world"/>
    <child link="right_g_base"/>
    <origin xyz= "0.25 0 0" rpy = "0 0 1.5708"/>
  </joint>


  <!-- Left Arm -->
  <link name="left_g_base">
    <visual>
      <geometry>
        <mesh filename="package://G_base.dae"/>
      </geometry>
      <origin xyz = "0.0 0 -0.03" rpy = "0 0 1.5708"/>
    </visual>
    <collision>
      <geometry>
        <mesh filename="package://G_base.dae"/>
      </geometry>
      <origin xyz = "0.0 0 -0.03" rpy = "0 0 1.5708"/>
    </collision>
  </link>

  <link name="left_joint1">
    <visual>
      <geometry>
	     <!--- 0.0 0 -0.04  1.5708 3.14159-->
       <mesh filename="package://joint1.dae"/>
      </geometry>
      <origin xyz = "0.0 0 0" rpy = "0 0 -1.5708"/>
    </visual>
    <collision>
      <geometry>
	     <!--- 0.0 0 -0.04  1.5708 3.14159-->
       <mesh filename="package://joint1.dae"/>
        </geometry>
        <origin xyz = "0.0 0 0" rpy = "0 0 -1.5708"/>
    </collision>
  </link>

  <link name="left_joint2">
    <visual>
      <geometry>
       <mesh filename="package://joint2.dae"/>
      </geometry>
      <origin xyz = "0.0 0 -0.06096" rpy = "0 0 -1.5708"/>
    </visual>
    <collision>
     <geometry>
       <mesh filename="package://joint2.dae"/>
      </geometry>
      <origin xyz = "0.0 0 -0.06096" rpy = "0 0 -1.5708"/>
    </collision>
  </link>


  <link name="left_joint3">
    <visual>
      <geometry>
       <mesh filename="package://joint3.dae"/>
      </geometry>
    <origin xyz = "0.0 0 0.03256" rpy = "0 -1.5708 0"/>
    </visual>
    <collision>
      <geometry>
       <mesh filename="package://joint3.dae"/>
      </geometry>
      <origin xyz = "0.0 0 0.03256" rpy = "0 -1.5708 0"/>
    </collision>
  </link>


  <link name="left_joint4">
    <visual>
      <geometry>
       <!--- 0.0 0 -0.04 -->
       <mesh filename="package://joint4.dae"/>
      </geometry>
      <origin xyz = "0.0 0 0.03056" rpy = "0 -1.5708 0"/>
    </visual>
    <collision>
      <geometry>
       <!--- 0.0 0 -0.04 -->
       <mesh filename="package://joint4.dae"/>
      </geometry>
      <origin xyz = "0.0 0 0.03056" rpy = "0 -1.5708 0"/>
    </collision>
  </link>


  <link name="left_joint5">
    <visual>
      <geometry>
       <!--- 0.0 0 -0.04 -->
       <mesh filename="package://joint5.dae"/>
      </geometry>
    <origin xyz = "0.0 0 -0.03356" rpy = "-1.5708 0 0"/>
    </visual>
    <collision>
       <geometry>
       <!--- 0.0 0 -0.04 -->
       <mesh filename="package://joint5.dae"/>
      </geometry>
      <origin xyz = "0.0 0 -0.03356" rpy = "-1.5708 0 0"/>
    </collision>
  </link>


  <link name="left_joint6">
    <visual>
      <geometry>
       <!--- 0.0 0 -0.04 -->
       <mesh filename="package://joint6.dae"/>
      </geometry>
    <origin xyz = "0 0.00 -0.038" rpy = "0 0 0"/>
    </visual>
    <collision>
      <geometry>
       <!--- 0.0 0 -0.04 -->
       <mesh filename="package://joint6.dae"/>
      </geometry>
    <origin xyz = "0 0.00 -0.038" rpy = "0 0 0"/>
    </collision>
  </link>


  <link name="left_joint6_flange">
    <visual>
      <geometry>
       <!--- 0.0 0 -0.04 -->
       <mesh filename="package://joint7.dae"/>
      </geometry>
    <origin xyz = "0.0 0 -0.012" rpy = "0 0 0"/>
    </visual>
    <collision>
      <geometry>
       <!--- 0.0 0 -0.04 -->
       <mesh filename="package://joint7.dae"/>
      </geometry>
    <origin xyz = "0.0 0 -0.012" rpy = "0 0 0"/>
    </collision>
  </link>

  <link name="left_gripper_base">
    <visual>
      <geometry>
       <!--- 0.0 0 -0.04 -->
       <mesh filename="package://gripper_base.dae"/>
      </geometry>
    <origin xyz = "0.0 0 -0.012" rpy = "0 0 0"/>
    </visual>
    <collision>
      <geometry>
       <!--- 0.0 0 -0.04 -->
       <mesh filename="package://gripper_base.dae"/>
      </geometry>
    <origin xyz = "0.0 0 -0.012" rpy = "0 0 0"/>
    </collision>
  </link>

  <link name="left_gripper_left1">
    <visual>
      <geometry>
       <!--- 0.0 0 -0.04 -->
       <mesh filename="package://gripper_left1.dae"/>
      </geometry>
    <origin xyz = "0.039 -0.0133 -0.012" rpy = "0 0 0"/>
    <!-- <origin xyz = "0.0 0 -0.012" rpy = "0 0 0"/> -->
    </visual>
    <collision>
      <geometry>
       <mesh filename="package://gripper_left1.dae"/>
      </geometry>
        <origin xyz = "0.039 -0.0133 -0.012" rpy = "0 0 0"/>
    </collision>
  </link>

  <link name="left_gripper_left2">
    <visual>
      <geometry>
       <mesh filename="package://gripper_left2.dae"/>
      </geometry>
    <origin xyz = "0.005 -0.0195 -0.012" rpy = "0 0 0"/>
    </visual>
    <collision>
      <geometry>
       <mesh filename="package://gripper_left2.dae"/>
      </geometry>
        <origin xyz = "0.005 -0.0195 -0.012" rpy = "0 0 0"/>
    </collision>
  </link>

  <link name="left_gripper_left3">
    <visual>
      <geometry>
       <mesh filename="package://gripper_left3.dae"/>
      </geometry>
    <origin xyz = "0.012 0.0025 -0.012" rpy = "0 0 0"/>
    <!-- <origin xyz = "0.0 0 0" rpy = "0 0 0"/> -->

    </visual>
    <collision>
      <geometry>
       <mesh filename="package://gripper_left3.dae"/>
      </geometry>
    <origin xyz = "0.012 0.0025 -0.012" rpy = "0 0 0"/>
    </collision>
  </link>

  <link name="left_gripper_right1">
    <visual>
      <geometry>
       <mesh filename="package://gripper_right1.dae"/>
      </geometry>
    <origin xyz = "-0.039 -0.0133 -0.012" rpy = "0 0 0"/>
    </visual>
    <collision>
      <geometry>
       <mesh filename="package://gripper_right1.dae"/>
      </geometry>
        <origin xyz = "-0.039 -0.0133 -0.012" rpy = "0 0 0"/>
    </collision>
  </link>

  <link name="left_gripper_right2">
    <visual>
      <geometry>
       <mesh filename="package://gripper_right2.dae"/>
      </geometry>
    <origin xyz = "-0.005 -0.0195 -0.012" rpy = "0 0 0"/>
    </visual>
    <collision>
      <geometry>
       <mesh filename="package://gripper_right2.dae"/>
      </geometry>
        <origin xyz = "-0.005 -0.0195 -0.012" rpy = "0 0 0"/>
    </collision>
  </link>

  <link name="left_gripper_right3">
    <visual>
      <geometry>
       <mesh filename="package://gripper_right3.dae"/>
      </geometry>
    <origin xyz = "-0.012 0.0025 -0.012" rpy = "0 0 0"/>
    </visual>
    <collision>
      <geometry>
       <mesh filename="package://gripper_right3.dae"/>
      </geometry>
    <origin xyz = "-0.012 0.0025 -0.012" rpy = "0 0 0"/>
    </collision>
  </link>


  <joint name="left_g_base_to_joint1" type="fixed">
    <axis xyz="0 0 0"/>
    <limit effort = "1000.0" lower = "-3.14" upper = "3.14159" velocity = "0"/>
    <parent link="left_g_base"/>
    <child link="left_joint1"/>
    <origin xyz= "0 0 0" rpy = "0 0 0"/>  
  </joint>

  <joint name="left_joint2_to_joint1" type="revolute">
    <axis xyz="0 0 1"/>
    <limit effort = "1000.0" lower = "-2.879793" upper = "2.879793" velocity = "0"/>
    <parent link="left_joint1"/>
    <child link="left_joint2"/>
    <origin xyz= "0 0 0.13156" rpy = "0 0 0"/>  
  </joint>


  <joint name="left_joint3_to_joint2" type="revolute">
    <axis xyz="0 0 1"/>
    <limit effort = "1000.0" lower = "-2.879793" upper = "1.0" velocity = "0"/>
    <parent link="left_joint2"/>
    <child link="left_joint3"/>
    <origin xyz= "0 0 0" rpy = "0 1.5708 -1.5708"/>  
  </joint>


  <joint name="left_joint4_to_joint3" type="revolute">
    <axis xyz="0 0 1"/>
    <limit effort = "1000.0" lower = "-2.789793" upper = "-0.1" velocity = "0"/>
    <parent link="left_joint3"/>
    <child link="left_joint4"/>
    <origin xyz= "-0.1104 0 0" rpy = "0 0 0"/>  
  </joint>


  <joint name="left_joint5_to_joint4" type="revolute">
    <axis xyz="0 0 1"/>
    <limit effort = "1000.0" lower = "-0.8" upper = "2.49793" velocity = "0"/>
    <parent link="left_joint4"/>
    <child link="left_joint5"/>
    <origin xyz= "-0.096 0 0.06462" rpy = "0 0 -1.5708"/>  
  </joint>

  <joint name="left_joint6_to_joint5" type="revolute">
    <axis xyz="0 0 1"/>
    <limit effort = "1000.0" lower = "-2.879793" upper = "2.879793" velocity = "0"/>
    <parent link="left_joint5"/>
    <child link="left_joint6"/>
    <origin xyz= "0 -0.07318 0" rpy = "1.5708 -1.5708 0"/>  
  </joint>

  <joint name="left_joint6output_to_joint6" type="revolute">
    <axis xyz="0 0 1"/>
    <limit effort = "1000.0" lower = "-3.05" upper = "3.05" velocity = "0"/>
    <parent link="left_joint6"/>
    <child link="left_joint6_flange"/>
    <origin xyz= "0 0.0456 0" rpy = "-1.5708 -2.3562 0"/>  
  </joint>

  <joint name="left_joint6output_to_gripper_base" type="fixed">
    <!-- <axis xyz="0 0 1"/>
    <limit effort = "1000.0" lower = "0" upper = "0" velocity = "0"/> -->
    <axis xyz="0 0 1"/>
    <limit effort = "1000.0" lower = "0" upper = "0" velocity = "0"/> 
    <parent link="left_joint6_flange"/>
    <child link="left_gripper_base"/>
    <!-- <origin xyz= "0 0.0 0" rpy = "-1.5708 0 0"/>   -->
    <origin xyz= "0 0 0.034" rpy = "1.579 0 3.1415"/>  
  </joint>

  <link name="left_gripper_tip">
    <origin xyz= "0 0 0" rpy = "0 0 0"/>  
  </link>
  <joint name="left_gripper_tip_to_gripper_base" type="fixed">
    <parent link="left_gripper_base"/>
    <child link="left_gripper_tip"/>
    <origin xyz= "0 0.065 -0.01" rpy = "0 0 0"/>  
  </joint>


  <joint name="left_gripper_controller" type="revolute">
    <axis xyz="0 0 1"/>
    <limit effort = "1000.0" lower = "-0.7" upper = "0.15" velocity = "0"/>
    <parent link="left_gripper_base"/>
    <child link="left_gripper_left3"/>
    <origin xyz= "-0.012 0.005 0" rpy = "0 0 0"/> 
  </joint>

  <joint name="left_gripper_base_to_gripper_left2" type="revolute">
    <axis xyz="0 0 1"/>
    <limit effort = "1000.0" lower = "-0.8" upper = "0.5" velocity = "0"/>
    <parent link="left_gripper_base"/>
    <child link="left_gripper_left2"/>
    <origin xyz= "-0.005 0.027 0" rpy = "0 0 0"/> 
    <mimic joint="left_gripper_controller" multiplier="1.0" offset="0" />
  </joint>

  <joint name="left_gripper_left3_to_gripper_left1" type="revolute">
    <axis xyz="0 0 1"/>
    <limit effort = "1000.0" lower = "-0.5" upper = "0.7" velocity = "0"/>
    <parent link="left_gripper_left3"/>
    <child link="left_gripper_left1"/>
    <origin xyz= "-0.027 0.016 0" rpy = "0 0 0"/> 
    <mimic joint="left_gripper_controller" multiplier="-1.0" offset="0" />
  </joint>


  <joint name="left_gripper_base_to_gripper_right3" type="revolute">
    <axis xyz="0 0 1"/>
    <limit effort = "1000.0" lower = "-0.15" upper = "0.7" velocity = "0"/>
    <parent link="left_gripper_base"/>
    <child link="left_gripper_right3"/>
    <origin xyz= "0.012 0.005 0" rpy = "0 0 0"/> 
    <mimic joint="left_gripper_controller" multiplier="-1.0" offset="0" />
  </joint>

  <joint name="left_gripper_base_to_gripper_right2" type="revolute">
    <axis xyz="0 0 1"/>
    <limit effort = "1000.0" lower = "-0.5" upper = "0.8" velocity = "0"/>
    <parent link="left_gripper_base"/>
    <child link="left_gripper_right2"/>
    <origin xyz= "0.005 0.027 0" rpy = "0 0 0"/> 
    <mimic joint="left_gripper_controller" multiplier="-1.0" offset="0" />
  </joint>

  <joint name="left_gripper_right3_to_gripper_right1" type="revolute">
    <axis xyz="0 0 1"/>
    <limit effort = "1000.0" lower = "-0.7" upper = "0.5" velocity = "0"/>
    <parent link="left_gripper_right3"/>
    <child link="left_gripper_right1"/>
    <origin xyz= "0.027 0.016 0" rpy = "0 0 0"/> 
    <mimic joint="left_gripper_controller" multiplier="1.0" offset="0" />
  </joint>


  <!-- Right Arm -->
  <link name="right_g_base">
    <visual>
      <geometry>
        <mesh filename="package://G_base.dae"/>
      </geometry>
      <origin xyz = "0.0 0 -0.03" rpy = "0 0 1.5708"/>
    </visual>
    <collision>
      <geometry>
        <mesh filename="package://G_base.dae"/>
      </geometry>
      <origin xyz = "0.0 0 -0.03" rpy = "0 0 1.5708"/>
    </collision>
  </link>

  <link name="right_joint1">
    <visual>
      <geometry>
	     <!--- 0.0 0 -0.04  1.5708 3.14159-->
       <mesh filename="package://joint1.dae"/>
      </geometry>
      <origin xyz = "0.0 0 0" rpy = "0 0 -1.5708"/>
    </visual>
    <collision>
      <geometry>
	     <!--- 0.0 0 -0.04  1.5708 3.14159-->
       <mesh filename="package://joint1.dae"/>
        </geometry>
        <origin xyz = "0.0 0 0" rpy = "0 0 -1.5708"/>
    </collision>
  </link>

  <link name="right_joint2">
    <visual>
      <geometry>
       <mesh filename="package://joint2.dae"/>
      </geometry>
      <origin xyz = "0.0 0 -0.06096" rpy = "0 0 -1.5708"/>
    </visual>
    <collision>
     <geometry>
       <mesh filename="package://joint2.dae"/>
      </geometry>
      <origin xyz = "0.0 0 -0.06096" rpy = "0 0 -1.5708"/>
    </collision>
  </link>


  <link name="right_joint3">
    <visual>
      <geometry>
       <mesh filename="package://joint3.dae"/>
      </geometry>
    <origin xyz = "0.0 0 0.03256" rpy = "0 -1.5708 0"/>
    </visual>
    <collision>
      <geometry>
       <mesh filename="package://joint3.dae"/>
      </geometry>
      <origin xyz = "0.0 0 0.03256" rpy = "0 -1.5708 0"/>
    </collision>
  </link>


  <link name="right_joint4">
    <visual>
      <geometry>
       <!--- 0.0 0 -0.04 -->
       <mesh filename="package://joint4.dae"/>
      </geometry>
      <origin xyz = "0.0 0 0.03056" rpy = "0 -1.5708 0"/>
    </visual>
    <collision>
      <geometry>
       <!--- 0.0 0 -0.04 -->
       <mesh filename="package://joint4.dae"/>
      </geometry>
      <origin xyz = "0.0 0 0.03056" rpy = "0 -1.5708 0"/>
    </collision>
  </link>


  <link name="right_joint5">
    <visual>
      <geometry>
       <!--- 0.0 0 -0.04 -->
       <mesh filename="package://joint5.dae"/>
      </geometry>
    <origin xyz = "0.0 0 -0.03356" rpy = "-1.5708 0 0"/>
    </visual>
    <collision>
       <geometry>
       <!--- 0.0 0 -0.04 -->
       <mesh filename="package://joint5.dae"/>
      </geometry>
      <origin xyz = "0.0 0 -0.03356" rpy = "-1.5708 0 0"/>
    </collision>
  </link>


  <link name="right_joint6">
    <visual>
      <geometry>
       <!--- 0.0 0 -0.04 -->
       <mesh filename="package://joint6.dae"/>
      </geometry>
    <origin xyz = "0 0.00 -0.038" rpy = "0 0 0"/>
    </visual>
    <collision>
      <geometry>
       <!--- 0.0 0 -0.04 -->
       <mesh filename="package://joint6.dae"/>
      </geometry>
    <origin xyz = "0 0.00 -0.038" rpy = "0 0 0"/>
    </collision>
  </link>


  <link name="right_joint6_flange">
    <visual>
      <geometry>
       <!--- 0.0 0 -0.04 -->
       <mesh filename="package://joint7.dae"/>
      </geometry>
    <origin xyz = "0.0 0 -0.012" rpy = "0 0 0"/>
    </visual>
    <collision>
      <geometry>
       <!--- 0.0 0 -0.04 -->
       <mesh filename="package://joint7.dae"/>
      </geometry>
    <origin xyz = "0.0 0 -0.012" rpy = "0 0 0"/>
    </collision>
  </link>

  <link name="right_gripper_base">
    <visual>
      <geometry>
       <!--- 0.0 0 -0.04 -->
       <mesh filename="package://gripper_base.dae"/>
      </geometry>
    <origin xyz = "0.0 0 -0.012" rpy = "0 0 0"/>
    </visual>
    <collision>
      <geometry>
       <!--- 0.0 0 -0.04 -->
       <mesh filename="package://gripper_base.dae"/>
      </geometry>
    <origin xyz = "0.0 0 -0.012" rpy = "0 0 0"/>
    </collision>
  </link>

  <link name="right_gripper_left1">
    <visual>
      <geometry>
       <!--- 0.0 0 -0.04 -->
       <mesh filename="package://gripper_left1.dae"/>
      </geometry>
    <origin xyz = "0.039 -0.0133 -0.012" rpy = "0 0 0"/>
    <!-- <origin xyz = "0.0 0 -0.012" rpy = "0 0 0"/> -->
    </visual>
    <collision>
      <geometry>
       <mesh filename="package://gripper_left1.dae"/>
      </geometry>
        <origin xyz = "0.039 -0.0133 -0.012" rpy = "0 0 0"/>
    </collision>
  </link>

  <link name="right_gripper_left2">
    <visual>
      <geometry>
       <mesh filename="package://gripper_left2.dae"/>
      </geometry>
    <origin xyz = "0.005 -0.0195 -0.012" rpy = "0 0 0"/>
    </visual>
    <collision>
      <geometry>
       <mesh filename="package://gripper_left2.dae"/>
      </geometry>
        <origin xyz = "0.005 -0.0195 -0.012" rpy = "0 0 0"/>
    </collision>
  </link>

  <link name="right_gripper_left3">
    <visual>
      <geometry>
       <mesh filename="package://gripper_left3.dae"/>
      </geometry>
    <origin xyz = "0.012 0.0025 -0.012" rpy = "0 0 0"/>
    <!-- <origin xyz = "0.0 0 0" rpy = "0 0 0"/> -->

    </visual>
    <collision>
      <geometry>
       <mesh filename="package://gripper_left3.dae"/>
      </geometry>
    <origin xyz = "0.012 0.0025 -0.012" rpy = "0 0 0"/>
    </collision>
  </link>

  <link name="right_gripper_right1">
    <visual>
      <geometry>
       <mesh filename="package://gripper_right1.dae"/>
      </geometry>
    <origin xyz = "-0.039 -0.0133 -0.012" rpy = "0 0 0"/>
    </visual>
    <collision>
      <geometry>
       <mesh filename="package://gripper_right1.dae"/>
      </geometry>
        <origin xyz = "-0.039 -0.0133 -0.012" rpy = "0 0 0"/>
    </collision>
  </link>

  <link name="right_gripper_right2">
    <visual>
      <geometry>
       <mesh filename="package://gripper_right2.dae"/>
      </geometry>
    <origin xyz = "-0.005 -0.0195 -0.012" rpy = "0 0 0"/>
    </visual>
    <collision>
      <geometry>
       <mesh filename="package://gripper_right2.dae"/>
      </geometry>
        <origin xyz = "-0.005 -0.0195 -0.012" rpy = "0 0 0"/>
    </collision>
  </link>

  <link name="right_gripper_right3">
    <visual>
      <geometry>
       <mesh filename="package://gripper_right3.dae"/>
      </geometry>
    <origin xyz = "-0.012 0.0025 -0.012" rpy = "0 0 0"/>
    </visual>
    <collision>
      <geometry>
       <mesh filename="package://gripper_right3.dae"/>
      </geometry>
    <origin xyz = "-0.012 0.0025 -0.012" rpy = "0 0 0"/>
    </collision>
  </link>


  <joint name="right_g_base_to_joint1" type="fixed">
    <axis xyz="0 0 0"/>
    <limit effort = "1000.0" lower = "-3.14" upper = "3.14159" velocity = "0"/>
    <parent link="right_g_base"/>
    <child link="right_joint1"/>
    <origin xyz= "0 0 0" rpy = "0 0 0"/>  
  </joint>

  <joint name="right_joint2_to_joint1" type="revolute">
    <axis xyz="0 0 1"/>
    <limit effort = "1000.0" lower = "-2.879793" upper = "2.879793" velocity = "0"/>
    <parent link="right_joint1"/>
    <child link="right_joint2"/>
    <origin xyz= "0 0 0.13156" rpy = "0 0 0"/>  
  </joint>


  <joint name="right_joint3_to_joint2" type="revolute">
    <axis xyz="0 0 1"/>
    <limit effort = "1000.0" lower = "-2.879793" upper = "1.0" velocity = "0"/>
    <parent link="right_joint2"/>
    <child link="right_joint3"/>
    <origin xyz= "0 0 0" rpy = "0 1.5708 -1.5708"/>  
  </joint>


  <joint name="right_joint4_to_joint3" type="revolute">
    <axis xyz="0 0 1"/>
    <limit effort = "1000.0" lower = "-2.789793" upper = "-0.1" velocity = "0"/>
    <parent link="right_joint3"/>
    <child link="right_joint4"/>
    <origin xyz= "-0.1104 0 0" rpy = "0 0 0"/>  
  </joint>


  <joint name="right_joint5_to_joint4" type="revolute">
    <axis xyz="0 0 1"/>
    <limit effort = "1000.0" lower = "-0.8" upper = "2.49793" velocity = "0"/>
    <parent link="right_joint4"/>
    <child link="right_joint5"/>
    <origin xyz= "-0.096 0 0.06462" rpy = "0 0 -1.5708"/>  
  </joint>

  <joint name="right_joint6_to_joint5" type="revolute">
    <axis xyz="0 0 1"/>
    <limit effort = "1000.0" lower = "-2.879793" upper = "2.879793" velocity = "0"/>
    <parent link="right_joint5"/>
    <child link="right_joint6"/>
    <origin xyz= "0 -0.07318 0" rpy = "1.5708 -1.5708 0"/>  
  </joint>

  <joint name="right_joint6output_to_joint6" type="revolute">
    <axis xyz="0 0 1"/>
    <limit effort = "1000.0" lower = "-3.05" upper = "3.05" velocity = "0"/>
    <parent link="right_joint6"/>
    <child link="right_joint6_flange"/>
    <origin xyz= "0 0.0456 0" rpy = "-1.5708 -2.3562 0"/>  
  </joint>

  <joint name="right_joint6output_to_gripper_base" type="fixed">
    <!-- <axis xyz="0 0 1"/>
    <limit effort = "1000.0" lower = "-3.14" upper = "3.14159" velocity = "0"/> -->
    <parent link="right_joint6_flange"/>
    <child link="right_gripper_base"/>
    <!-- <origin xyz= "0 0.0 0" rpy = "-1.5708 0 0"/>   -->
    <origin xyz= "0 0 0.034" rpy = "1.579 0 3.1415"/>  
  </joint>

  <link name="right_gripper_tip">
    <origin xyz= "0 0 0" rpy = "0 0 0"/>  
  </link>
  <joint name="right_gripper_tip_to_gripper_base" type="fixed">
    <parent link="right_gripper_base"/>
    <child link="right_gripper_tip"/>
    <origin xyz= "0 0.065 -0.01" rpy = "0 0 0"/>  
  </joint>


  <joint name="right_gripper_controller" type="revolute">
    <axis xyz="0 0 1"/>
    <limit effort = "1000.0" lower = "-0.7" upper = "0.15" velocity = "0"/>
    <parent link="right_gripper_base"/>
    <child link="right_gripper_left3"/>
    <origin xyz= "-0.012 0.005 0" rpy = "0 0 0"/> 
  </joint>

  <joint name="right_gripper_base_to_gripper_left2" type="revolute">
    <axis xyz="0 0 1"/>
    <limit effort = "1000.0" lower = "-0.8" upper = "0.5" velocity = "0"/>
    <parent link="right_gripper_base"/>
    <child link="right_gripper_left2"/>
    <origin xyz= "-0.005 0.027 0" rpy = "0 0 0"/> 
    <mimic joint="right_gripper_controller" multiplier="1.0" offset="0" />
  </joint>

  <joint name="right_gripper_left3_to_gripper_left1" type="revolute">
    <axis xyz="0 0 1"/>
    <limit effort = "1000.0" lower = "-0.5" upper = "0.7" velocity = "0"/>
    <parent link="right_gripper_left3"/>
    <child link="right_gripper_left1"/>
    <origin xyz= "-0.027 0.016 0" rpy = "0 0 0"/> 
    <mimic joint="right_gripper_controller" multiplier="-1.0" offset="0" />
  </joint>


  <joint name="right_gripper_base_to_gripper_right3" type="revolute">
    <axis xyz="0 0 1"/>
    <limit effort = "1000.0" lower = "-0.15" upper = "0.7" velocity = "0"/>
    <parent link="right_gripper_base"/>
    <child link="right_gripper_right3"/>
    <origin xyz= "0.012 0.005 0" rpy = "0 0 0"/> 
    <mimic joint="right_gripper_controller" multiplier="-1.0" offset="0" />
  </joint>

  <joint name="right_gripper_base_to_gripper_right2" type="revolute">
    <axis xyz="0 0 1"/>
    <limit effort = "1000.0" lower = "-0.5" upper = "0.8" velocity = "0"/>
    <parent link="right_gripper_base"/>
    <child link="right_gripper_right2"/>
    <origin xyz= "0.005 0.027 0" rpy = "0 0 0"/> 
    <mimic joint="right_gripper_controller" multiplier="-1.0" offset="0" />
  </joint>

  <joint name="right_gripper_right3_to_gripper_right1" type="revolute">
    <axis xyz="0 0 1"/>
    <limit effort = "1000.0" lower = "-0.7" upper = "0.5" velocity = "0"/>
    <parent link="right_gripper_right3"/>
    <child link="right_gripper_right1"/>
    <origin xyz= "0.027 0.016 0" rpy = "0 0 0"/> 
    <mimic joint="right_gripper_controller" multiplier="1.0" offset="0" />
  </joint>

</robot>
